Workbook

Sheet Budget
A1: Object | B1: Total of years | G1: Previous years | L1: 2024 | Q1: 2025 | V1: 2026 | AA1: 2027 and Following | AF1: Overall values | AK1: ProjectName | AL1: ProjectID | AM1: =B1 -> Total of years | AN1: Plan Values across years
B2: Budget | C2: Actual | D2: Commitment | E2: Assigned | F2: Available | G2: Budget | H2: Actual | I2: Commitment | J2: Assigned | K2: Available | L2: Budget | M2: Actual | N2: Commitment | O2: Assigned | P2: Available | Q2: Budget | R2: Actual | S2: Commitment | T2: Assigned | U2: Available | V2: Budget | W2: Actual | X2: Commitment | Y2: Assigned | Z2: Available | AA2: Budget | AB2: Actual | AC2: Commitment | AD2: Assigned | AE2: Available | AF2: Budget | AG2: Actual | AH2: Commitment | AI2: Assigned | AJ2: Available | AN2: =G1 -> Previous years | AO2: =L1 -> 2024 | AP2: =Q1 -> 2025 | AQ2: =V1 -> 2026 | AR2: =AA1 -> 2027 and Following | AS2: =AF1 -> Overall values
A3: 6* 600 MW Solar @ GSECL PRJ NG-C-SOL-001 | B3: 0 | C3: 0 | D3: 0 | E3: 0 | F3: 0 | G3: 0 | H3: 0 | I3: 0 | J3: 0 | K3: 0 | L3: 0 | M3: 0 | N3: 0 | O3: 0 | P3: 0 | Q3: 0 | R3: 0 | S3: 0 | T3: 0 | U3: 0 | V3: 0 | W3: 0 | X3: 0 | Y3: 0 | Z3: 0 | AA3: 0 | AB3: 0 | AC3: 0 | AD3: 0 | AE3: 0 | AF3: 0 | AG3: 0 | AH3: 0 | AI3: 0 | AJ3: 0 | AK3: 600 MW Solar @ GSECL | AL3: NG-C-SOL-001 | AM3: =VLOOKUP(AL3,Table1[],2,FALSE) -> #N/A | AN3: =VLOOKUP($AL3,Table1[],3,FALSE) -> #N/A | AO3: =VLOOKUP($AL3,Table1[],4,FALSE) -> #N/A | AP3: =VLOOKUP($AL3,Table1[],5,FALSE) -> #N/A | AQ3: =VLOOKUP($AL3,Table1[],6,FALSE) -> #N/A | AR3: =VLOOKUP($AL3,Table1[],7,FALSE) -> #N/A | AS3: =VLOOKUP($AL3,Table1[],8,FALSE) -> #N/A
A4: 6* 300 MW Solar Power P PRJ NL-C-BSP-001 | B4: 1.9137258e+10 | C4: 4.6622641e+09 | D4: 1.2756415e+09 | E4: 5.9379056e+09 | F4: 1.3199352e+10 | G4: 1.9527548e+09 | H4: 1.9527548e+09 | I4: 0 | J4: 1.9527548e+09 | K4: 0 | L4: 1.7184503e+10 | M4: 2.7095093e+09 | N4: 1.2756415e+09 | O4: 3.9851508e+09 | P4: 1.3199352e+10 | Q4: 0 | R4: 0 | S4: 0 | T4: 0 | U4: 0 | V4: 0 | W4: 0 | X4: 0 | Y4: 0 | Z4: 0 | AA4: 0 | AB4: 0 | AC4: 0 | AD4: 0 | AE4: 0 | AF4: 1.9137258e+10 | AG4: 4.6622641e+09 | AH4: 1.2756415e+09 | AI4: 5.9379056e+09 | AJ4: 1.3199352e+10 | AK4: 300 MW Solar Power P | AL4: NL-C-BSP-001 | AM4: =VLOOKUP(AL4,Table1[],2,FALSE) -> 17555000001 | AN4: =VLOOKUP(AL4,Table1[],3,FALSE) -> 17555000001 | AO4: =VLOOKUP($AL4,Table1[],4,FALSE) -> 0 | AP4: =VLOOKUP($AL4,Table1[],5,FALSE) -> 0 | AQ4: =VLOOKUP($AL4,Table1[],6,FALSE) -> 0 | AR4: =VLOOKUP($AL4,Table1[],7,FALSE) -> 0 | AS4: =VLOOKUP($AL4,Table1[],8,FALSE) -> 17575000001
A5: 6* CARD R&D Project PRJ NL-C-CRD-001 | B5: 0 | C5: 0 | D5: 0 | E5: 0 | F5: 0 | G5: 0 | H5: 0 | I5: 0 | J5: 0 | K5: 0 | L5: 0 | M5: 0 | N5: 0 | O5: 0 | P5: 0 | Q5: 0 | R5: 0 | S5: 0 | T5: 0 | U5: 0 | V5: 0 | W5: 0 | X5: 0 | Y5: 0 | Z5: 0 | AA5: 0 | AB5: 0 | AC5: 0 | AD5: 0 | AE5: 0 | AF5: 0 | AG5: 0 | AH5: 0 | AI5: 0 | AJ5: 0 | AK5: CARD R&D Project | AL5: NL-C-CRD-001 | AM5: =VLOOKUP(AL5,Table1[],2,FALSE) -> #N/A | AN5: =VLOOKUP(AL5,Table1[],3,FALSE) -> #N/A | AO5: =VLOOKUP($AL5,Table1[],4,FALSE) -> #N/A | AP5: =VLOOKUP($AL5,Table1[],5,FALSE) -> #N/A | AQ5: =VLOOKUP($AL5,Table1[],6,FALSE) -> #N/A | AR5: =VLOOKUP($AL5,Table1[],7,FALSE) -> #N/A | AS5: =VLOOKUP($AL5,Table1[],8,FALSE) -> #N/A
A6: 6* Lignite to disel cap PRJ NL-C-CRD-002 | B6: 3987309 | C6: 3987309 | D6: 0 | E6: 3987309 | F6: 0 | G6: 3987309 | H6: 3987309 | I6: 0 | J6: 3987309 | K6: 0 | L6: 0 | M6: 0 | N6: 0 | O6: 0 | P6: 0 | Q6: 0 | R6: 0 | S6: 0 | T6: 0 | U6: 0 | V6: 0 | W6: 0 | X6: 0 | Y6: 0 | Z6: 0 | AA6: 0 | AB6: 0 | AC6: 0 | AD6: 0 | AE6: 0 | AF6: 3987309 | AG6: 3987309 | AH6: 0 | AI6: 3987309 | AJ6: 0 | AK6: Lignite to disel cap | AL6: NL-C-CRD-002 | AM6: =VLOOKUP(AL6,Table1[],2,FALSE) -> 5945634 | AN6: =VLOOKUP(AL6,Table1[],3,FALSE) -> 5945634 | AO6: =VLOOKUP($AL6,Table1[],4,FALSE) -> 0 | AP6: =VLOOKUP($AL6,Table1[],5,FALSE) -> 0 | AQ6: =VLOOKUP($AL6,Table1[],6,FALSE) -> 0 | AR6: =VLOOKUP($AL6,Table1[],7,FALSE) -> 0 | AS6: =VLOOKUP($AL6,Table1[],8,FALSE) -> 5945634
A7: 6* CARD-IITM-Developmen PRJ NL-C-CRD-003 | B7: 13294999 | C7: 3679142.1 | D7: 9615856.8 | E7: 13294999 | F7: 0 | G7: 13294999 | H7: 3679142.1 | I7: 9615856.8 | J7: 13294999 | K7: 0 | L7: 0 | M7: 0 | N7: 0 | O7: 0 | P7: 0 | Q7: 0 | R7: 0 | S7: 0 | T7: 0 | U7: 0 | V7: 0 | W7: 0 | X7: 0 | Y7: 0 | Z7: 0 | AA7: 0 | AB7: 0 | AC7: 0 | AD7: 0 | AE7: 0 | AF7: 13294999 | AG7: 3679142.1 | AH7: 9615856.8 | AI7: 13294999 | AJ7: 0 | AK7: CARD-IITM-Developmen | AL7: NL-C-CRD-003 | AM7: =VLOOKUP(AL7,Table1[],2,FALSE) -> 18295400 | AN7: =VLOOKUP(AL7,Table1[],3,FALSE) -> 18295400 | AO7: =VLOOKUP($AL7,Table1[],4,FALSE) -> 0 | AP7: =VLOOKUP($AL7,Table1[],5,FALSE) -> 0 | AQ7: =VLOOKUP($AL7,Table1[],6,FALSE) -> 0 | AR7: =VLOOKUP($AL7,Table1[],7,FALSE) -> 0 | AS7: =VLOOKUP($AL7,Table1[],8,FALSE) -> 18295400
A8: 6* CAPEX PROJECT FOR CA PRJ NL-C-CRD-004 | B8: 8.0681444e+08 | C8: 3.6219046e+08 | D8: 2.4664061e+08 | E8: 6.0883108e+08 | F8: 1.9798336e+08 | G8: 2.4180404e+08 | H8: 2.4180404e+08 | I8: 8813116 | J8: 2.5061716e+08 | K8: -8813116 | L8: 5.650104e+08 | M8: 1.2038642e+08 | N8: 2.3124675e+08 | O8: 3.5163317e+08 | P8: 2.1337722e+08 | Q8: 0 | R8: 0 | S8: 6580745.8 | T8: 6580745.8 | U8: -6580745.8 | V8: 0 | W8: 0 | X8: 0 | Y8: 0 | Z8: 0 | AA8: 0 | AB8: 0 | AC8: 0 | AD8: 0 | AE8: 0 | AF8: 8.0681444e+08 | AG8: 3.6219046e+08 | AH8: 2.4664061e+08 | AI8: 6.0883108e+08 | AJ8: 1.9798336e+08 | AK8: CAPEX PROJECT FOR CA | AL8: NL-C-CRD-004 | AM8: =VLOOKUP(AL8,Table1[],2,FALSE) -> 718500000 | AN8: =VLOOKUP(AL8,Table1[],3,FALSE) -> 718500000 | AO8: =VLOOKUP($AL8,Table1[],4,FALSE) -> 0 | AP8: =VLOOKUP($AL8,Table1[],5,FALSE) -> 0 | AQ8: =VLOOKUP($AL8,Table1[],6,FALSE) -> 0 | AR8: =VLOOKUP($AL8,Table1[],7,FALSE) -> 0 | AS8: =VLOOKUP($AL8,Table1[],8,FALSE) -> 718500000
A9: 6* Khavda Solar Power P PRJ NL-C-KSP-001 | B9: 398300.04 | C9: 375240 | D9: 23060.04 | E9: 398300.04 | F9: 0 | G9: 375240 | H9: 375240 | I9: 0 | J9: 375240 | K9: 0 | L9: 23060.04 | M9: 0 | N9: 23060.04 | O9: 23060.04 | P9: 0 | Q9: 0 | R9: 0 | S9: 0 | T9: 0 | U9: 0 | V9: 0 | W9: 0 | X9: 0 | Y9: 0 | Z9: 0 | AA9: 0 | AB9: 0 | AC9: 0 | AD9: 0 | AE9: 0 | AF9: 398300.04 | AG9: 375240 | AH9: 23060.04 | AI9: 398300.04 | AJ9: 0 | AK9: Khavda Solar Power P | AL9: NL-C-KSP-001 | AM9: =VLOOKUP(AL9,Table1[],2,FALSE) -> 33358500000 | AN9: =VLOOKUP(AL9,Table1[],3,FALSE) -> 33358500000 | AO9: =VLOOKUP($AL9,Table1[],4,FALSE) -> 0 | AP9: =VLOOKUP($AL9,Table1[],5,FALSE) -> 0 | AQ9: =VLOOKUP($AL9,Table1[],6,FALSE) -> 0 | AR9: =VLOOKUP($AL9,Table1[],7,FALSE) -> 0 | AS9: =VLOOKUP($AL9,Table1[],8,FALSE) -> 33358500000
A10: 6* Land Acquisiton Plan PRJ NL-C-LAQ-001 | B10: 5.4160222e+09 | C10: 3.7048729e+09 | D10: 68131781 | E10: 3.7730047e+09 | F10: 1.6430175e+09 | G10: 2374299156 | H10: 2374299156 | I10: 0 | J10: 2374299156 | K10: 0 | L10: 3.0417231e+09 | M10: 1.3305738e+09 | N10: 68131781 | O10: 1.3987056e+09 | P10: 1.6430175e+09 | Q10: 0 | R10: 0 | S10: 0 | T10: 0 | U10: 0 | V10: 0 | W10: 0 | X10: 0 | Y10: 0 | Z10: 0 | AA10: 0 | AB10: 0 | AC10: 0 | AD10: 0 | AE10: 0 | AF10: 5.4160222e+09 | AG10: 3.7048729e+09 | AH10: 68131781 | AI10: 3.7730047e+09 | AJ10: 1.6430175e+09 | AK10: Land Acquisiton Plan | AL10: NL-C-LAQ-001 | AM10: =VLOOKUP(AL10,Table1[],2,FALSE) -> 1400000000 | AN10: =VLOOKUP(AL10,Table1[],3,FALSE) -> 0 | AO10: =VLOOKUP($AL10,Table1[],4,FALSE) -> 1400000000 | AP10: =VLOOKUP($AL10,Table1[],5,FALSE) -> 0 | AQ10: =VLOOKUP($AL10,Table1[],6,FALSE) -> 0 | AR10: =VLOOKUP($AL10,Table1[],7,FALSE) -> 0 | AS10: =VLOOKUP($AL10,Table1[],8,FALSE) -> 1400000000
A11: 6* EXPANSION OF MINE-IA PRJ NL-C-MIA-001 | B11: 8.8952203e+08 | C11: 6.9805587e+08 | D11: 1.3365458e+08 | E11: 8.3171045e+08 | F11: 57811579 | G11: 3.998401e+08 | H11: 3.9960629e+08 | I11: 0 | J11: 3.9960629e+08 | K11: 233808.46 | L11: 4.8968193e+08 | M11: 2.9844958e+08 | N11: 1.2065071e+08 | O11: 4.1910029e+08 | P11: 70581637 | Q11: 0 | R11: 0 | S11: 13003867 | T11: 13003867 | U11: -13003867 | V11: 0 | W11: 0 | X11: 0 | Y11: 0 | Z11: 0 | AA11: 0 | AB11: 0 | AC11: 0 | AD11: 0 | AE11: 0 | AF11: 8.8952203e+08 | AG11: 6.9805587e+08 | AH11: 1.3365458e+08 | AI11: 8.3171045e+08 | AJ11: 57811579 | AK11: EXPANSION OF MINE-IA | AL11: NL-C-MIA-001 | AM11: =VLOOKUP(AL11,Table1[],2,FALSE) -> 359054495 | AN11: =VLOOKUP(AL11,Table1[],3,FALSE) -> 325589555 | AO11: =VLOOKUP($AL11,Table1[],4,FALSE) -> 33464940 | AP11: =VLOOKUP($AL11,Table1[],5,FALSE) -> 0 | AQ11: =VLOOKUP($AL11,Table1[],6,FALSE) -> 0 | AR11: =VLOOKUP($AL11,Table1[],7,FALSE) -> 0 | AS11: =VLOOKUP($AL11,Table1[],8,FALSE) -> 359054495
A12: 6* Mine 1 Capex Project PRJ NL-C-MN1-001 | B12: 0 | C12: 0 | D12: 0 | E12: 0 | F12: 0 | G12: 0 | H12: 0 | I12: 0 | J12: 0 | K12: 0 | L12: 0 | M12: 0 | N12: 0 | O12: 0 | P12: 0 | Q12: 0 | R12: 0 | S12: 0 | T12: 0 | U12: 0 | V12: 0 | W12: 0 | X12: 0 | Y12: 0 | Z12: 0 | AA12: 0 | AB12: 0 | AC12: 0 | AD12: 0 | AE12: 0 | AF12: 0 | AG12: 0 | AH12: 0 | AI12: 0 | AJ12: 0 | AK12: Mine 1 Capex Project | AL12: NL-C-MN1-001 | AM12: =VLOOKUP(AL12,Table1[],2,FALSE) -> 3390000000 | AN12: =VLOOKUP(AL12,Table1[],3,FALSE) -> 3390000000 | AO12: =VLOOKUP($AL12,Table1[],4,FALSE) -> 0 | AP12: =VLOOKUP($AL12,Table1[],5,FALSE) -> 0 | AQ12: =VLOOKUP($AL12,Table1[],6,FALSE) -> 0 | AR12: =VLOOKUP($AL12,Table1[],7,FALSE) -> 0 | AS12: =VLOOKUP($AL12,Table1[],8,FALSE) -> 3390000000
A13: 6* Mines III Capex Proj PRJ NL-C-MN3-001 | B13: 85900 | C13: 85892.2 | D13: 0 | E13: 85892.2 | F13: 7.8 | G13: 0 | H13: 0 | I13: 0 | J13: 0 | K13: 0 | L13: 85900 | M13: 85892.2 | N13: 0 | O13: 85892.2 | P13: 7.8 | Q13: 0 | R13: 0 | S13: 0 | T13: 0 | U13: 0 | V13: 0 | W13: 0 | X13: 0 | Y13: 0 | Z13: 0 | AA13: 0 | AB13: 0 | AC13: 0 | AD13: 0 | AE13: 0 | AF13: 85900 | AG13: 85892.2 | AH13: 0 | AI13: 85892.2 | AJ13: 7.8 | AK13: Mines III Capex Proj | AL13: NL-C-MN3-001 | AM13: =VLOOKUP(AL13,Table1[],2,FALSE) -> 37557200000 | AN13: =VLOOKUP(AL13,Table1[],3,FALSE) -> 37557200000 | AO13: =VLOOKUP($AL13,Table1[],4,FALSE) -> 0 | AP13: =VLOOKUP($AL13,Table1[],5,FALSE) -> 0 | AQ13: =VLOOKUP($AL13,Table1[],6,FALSE) -> 0 | AR13: =VLOOKUP($AL13,Table1[],7,FALSE) -> 0 | AS13: =VLOOKUP($AL13,Table1[],8,FALSE) -> 37557200000
A14: 6* Talabira II & III OC PRJ NL-C-MTL-001 | B14: 1640000000 | C14: 2.9246923e+09 | D14: 8.2433552e+08 | E14: 3.7490278e+09 | F14: -2.1090278e+09 | G14: 1640000000 | H14: 2.95219e+09 | I14: 8.2419552e+08 | J14: 3.7763855e+09 | K14: -2.1363855e+09 | L14: 0 | M14: -27497693 | N14: 0 | O14: -27497693 | P14: 27497693 | Q14: 0 | R14: 0 | S14: 140000.01 | T14: 140000.01 | U14: -140000.01 | V14: 0 | W14: 0 | X14: 0 | Y14: 0 | Z14: 0 | AA14: 0 | AB14: 0 | AC14: 0 | AD14: 0 | AE14: 0 | AF14: 1640000000 | AG14: 2.9246923e+09 | AH14: 8.2433552e+08 | AI14: 3.7490278e+09 | AJ14: -2.1090278e+09 | AK14: Talabira II & III OC | AL14: NL-C-MTL-001 | AM14: =VLOOKUP(AL14,Table1[],2,FALSE) -> 790000000 | AN14: =VLOOKUP(AL14,Table1[],3,FALSE) -> 790000000 | AO14: =VLOOKUP($AL14,Table1[],4,FALSE) -> 0 | AP14: =VLOOKUP($AL14,Table1[],5,FALSE) -> 0 | AQ14: =VLOOKUP($AL14,Table1[],6,FALSE) -> 0 | AR14: =VLOOKUP($AL14,Table1[],7,FALSE) -> 0 | AS14: =VLOOKUP($AL14,Table1[],8,FALSE) -> 790000000
A15: 6* Talabira II & III OC PRJ NL-C-MTL-002 | B15: 3.2296441e+09 | C15: 4.7821153e+08 | D15: 1.3806956e+09 | E15: 1.8589072e+09 | F15: 1.370737e+09 | G15: 1.0477658e+08 | H15: 93485870 | I15: 0 | J15: 93485870 | K15: 11290713 | L15: 3.1248676e+09 | M15: 3.8472566e+08 | N15: 1.3654743e+09 | O15: 1.7502e+09 | P15: 1.3746676e+09 | Q15: 0 | R15: 0 | S15: 15221329 | T15: 15221329 | U15: -15221329 | V15: 0 | W15: 0 | X15: 0 | Y15: 0 | Z15: 0 | AA15: 0 | AB15: 0 | AC15: 0 | AD15: 0 | AE15: 0 | AF15: 3.2296441e+09 | AG15: 4.7821153e+08 | AH15: 1.3806956e+09 | AI15: 1.8589072e+09 | AJ15: 1.370737e+09 | AK15: Talabira II & III OC | AL15: NL-C-MTL-002 | AM15: =VLOOKUP(AL15,Table1[],2,FALSE) -> 3500000000 | AN15: =VLOOKUP(AL15,Table1[],3,FALSE) -> 1500000000 | AO15: =VLOOKUP($AL15,Table1[],4,FALSE) -> 2000000000 | AP15: =VLOOKUP($AL15,Table1[],5,FALSE) -> 0 | AQ15: =VLOOKUP($AL15,Table1[],6,FALSE) -> 0 | AR15: =VLOOKUP($AL15,Table1[],7,FALSE) -> 0 | AS15: =VLOOKUP($AL15,Table1[],8,FALSE) -> 2700000000
... A411: 6* PSCB Feasibility Pro PRJ NU-F-MPS-001 | B411: 453345000 | C411: 0 | D411: 0 | E411: 0 | F411: 453345000 | G411: 453345000 | H411: 0 | I411: 0 | J411: 0 | K411: 453345000 | L411: 0 | M411: 0 | N411: 0 | O411: 0 | P411: 0 | Q411: 0 | R411: 0 | S411: 0 | T411: 0 | U411: 0 | V411: 0 | W411: 0 | X411: 0 | Y411: 0 | Z411: 0 | AA411: 0 | AB411: 0 | AC411: 0 | AD411: 0 | AE411: 0 | AF411: 453345000 | AG411: 0 | AH411: 0 | AI411: 0 | AJ411: 453345000 | AK411: PSCB Feasibility Pro | AL411: NU-F-MPS-001 | AM411: =VLOOKUP(AL411,Table1[],2,FALSE) -> 1771976000 | AN411: =VLOOKUP(AL411,Table1[],3,FALSE) -> 1771976000 | AO411: =VLOOKUP($AL411,Table1[],4,FALSE) -> 0 | AP411: =VLOOKUP($AL411,Table1[],5,FALSE) -> 0 | AQ411: =VLOOKUP($AL411,Table1[],6,FALSE) -> 0 | AR411: =VLOOKUP($AL411,Table1[],7,FALSE) -> 0 | AS411: =VLOOKUP($AL411,Table1[],8,FALSE) -> 885988000
A420: =B1 -> Total of years
A421: =G1 -> Previous years
A422: =L1 -> 2024
A423: =Q1 -> 2025
A424: =V1 -> 2026
A425: =AA1 -> 2027 and Following
A426: =AF1 -> Overall values

Sheet Actual
A1: ProjectID | B1: Total of years | C1: Previous years | D1: 2024 | E1: 2025 | F1: 2026 | G1: 2027 and Following | H1: Overall values
A2: NL-C-BSP-001 | B2: 17555000001 | C2: 17555000001 | D2: 0 | E2: 0 | F2: 0 | G2: 0 | H2: 17575000001
A3: NL-C-CRD-002 | B3: 5945634 | C3: 5945634 | D3: 0 | E3: 0 | F3: 0 | G3: 0 | H3: 5945634
A4: NL-C-CRD-003 | B4: 18295400 | C4: 18295400 | D4: 0 | E4: 0 | F4: 0 | G4: 0 | H4: 18295400
A5: NL-C-CRD-004 | B5: 718500000 | C5: 718500000 | D5: 0 | E5: 0 | F5: 0 | G5: 0 | H5: 718500000
A6: NL-C-KSP-001 | B6: 33358500000 | C6: 33358500000 | D6: 0 | E6: 0 | F6: 0 | G6: 0 | H6: 33358500000
A7: NL-C-LAQ-001 | B7: 1400000000 | C7: 0 | D7: 1400000000 | E7: 0 | F7: 0 | G7: 0 | H7: 1400000000
A8: NL-C-MIA-001 | B8: 359054495 | C8: 325589555 | D8: 33464940 | E8: 0 | F8: 0 | G8: 0 | H8: 359054495
A9: NL-C-MN1-001 | B9: 3390000000 | C9: 3390000000 | D9: 0 | E9: 0 | F9: 0 | G9: 0 | H9: 3390000000
A10: NL-C-MN3-001 | B10: 37557200000 | C10: 37557200000 | D10: 0 | E10: 0 | F10: 0 | G10: 0 | H10: 37557200000
A11: NL-C-MTL-001 | B11: 790000000 | C11: 790000000 | D11: 0 | E11: 0 | F11: 0 | G11: 0 | H11: 790000000
A12: NL-C-MTL-002 | B12: 3500000000 | C12: 1500000000 | D12: 2000000000 | E12: 0 | F12: 0 | G12: 0 | H12: 2700000000
A13: NL-C-NNT-001 | B13: 3787793152 | C13: 3787793152 | D13: 0 | E13: 0 | F13: 0 | G13: 0 | H13: 11092690297
... A290: NU-F-MPS-001 | B290: 1771976000 | C290: 1771976000 | D290: 0 | E290: 0 | F290: 0 | G290: 0 | H290: 885988000

Sheet Data
A1: Unnamed: 0_level_0_Budget | B1: Total of years_Budget | G1: Previous years_Budget | L1: 2024_Budget | Q1: 2025_Budget | V1: 2026_Budget | AA1: 2027 and Following_Budget | AF1: Overall values_Budget | AK1: ProjectName_Budget | AL1: ProjectID | AM1: Unnamed: 0_level_0_Actual | AN1: Total of years_Actual | AR1: Previous years_Actual | AV1: 2024_Actual | AZ1: 2025_Actual | BD1: 2026_Actual | BH1: 2027 and Following_Actual | BL1: Overall values_Actual | BP1: ProjectName_Actual
A2: Object | B2: Budget | C2: Actual | D2: Commitment | E2: Assigned | F2: Available | G2: Budget | H2: Actual | I2: Commitment | J2: Assigned | K2: Available | L2: Budget | M2: Actual | N2: Commitment | O2: Assigned | P2: Available | Q2: Budget | R2: Actual | S2: Commitment | T2: Assigned | U2: Available | V2: Budget | W2: Actual | X2: Commitment | Y2: Assigned | Z2: Available | AA2: Budget | AB2: Actual | AC2: Commitment | AD2: Assigned | AE2: Available | AF2: Budget | AG2: Actual | AH2: Commitment | AI2: Assigned | AJ2: Available | AM2: Object | AN2: Plan | AO2: Actual | AP2: Variance | AQ2: Var % | AR2: Plan | AS2: Actual | AT2: Variance | AU2: Var % | AV2: Plan | AW2: Actual | AX2: Variance | AY2: Var % | AZ2: Plan | BA2: Actual | BB2: Variance | BC2: Var % | BD2: Plan | BE2: Actual | BF2: Variance | BG2: Var % | BH2: Plan | BI2: Actual | BJ2: Variance | BK2: Var % | BL2: Plan | BM2: Actual | BN2: Variance | BO2: Var %
A3: 6* 600 MW Solar @ GSECL PRJ NG-C-SOL-001 | B3: 0 | C3: 0 | D3: 0 | E3: 0 | F3: 0 | G3: 0 | H3: 0 | I3: 0 | J3: 0 | K3: 0 | L3: 0 | M3: 0 | N3: 0 | O3: 0 | P3: 0 | Q3: 0 | R3: 0 | S3: 0 | T3: 0 | U3: 0 | V3: 0 | W3: 0 | X3: 0 | Y3: 0 | Z3: 0 | AA3: 0 | AB3: 0 | AC3: 0 | AD3: 0 | AE3: 0 | AF3: 0 | AG3: 0 | AH3: 0 | AI3: 0 | AJ3: 0 | AK3: 600 MW Solar @ GSECL | AL3: NG-C-SOL-001
A4: 6* 300 MW Solar Power P PRJ NL-C-BSP-001 | B4: 1.9137258e+10 | C4: 4.6622641e+09 | D4: 1.2756415e+09 | E4: 5.9379056e+09 | F4: 1.3199352e+10 | G4: 1.9527548e+09 | H4: 1.9527548e+09 | I4: 0 | J4: 1.9527548e+09 | K4: 0 | L4: 1.7184503e+10 | M4: 2.7095093e+09 | N4: 1.2756415e+09 | O4: 3.9851508e+09 | P4: 1.3199352e+10 | Q4: 0 | R4: 0 | S4: 0 | T4: 0 | U4: 0 | V4: 0 | W4: 0 | X4: 0 | Y4: 0 | Z4: 0 | AA4: 0 | AB4: 0 | AC4: 0 | AD4: 0 | AE4: 0 | AF4: 1.9137258e+10 | AG4: 4.6622641e+09 | AH4: 1.2756415e+09 | AI4: 5.9379056e+09 | AJ4: 1.3199352e+10 | AK4: 300 MW Solar Power P | AL4: NL-C-BSP-001 | AM4: 6* PRJ NL-C-BSP-001 300 MW Solar Power P | AN4: 17555000001 | AO4: 4662264095 | AP4: 12892735906 | AQ4: 73.4 | AR4: 17555000001 | AS4: 1952754815 | AT4: 15602245186 | AU4: 88.9 | AV4: 0 | AW4: 2709509279 | AX4: -2709509279 | AY4: 0 | AZ4: 0 | BA4: 0 | BB4: 0 | BC4: 0 | BD4: 0 | BE4: 0 | BF4: 0 | BG4: 0 | BH4: 0 | BI4: 0 | BJ4: 0 | BK4: 0 | BL4: 17575000001 | BM4: 4662264095 | BN4: 12912735906 | BO4: 73.5 | BP4: 300 MW Solar Power P
A5: 6* CARD R&D Project PRJ NL-C-CRD-001 | B5: 0 | C5: 0 | D5: 0 | E5: 0 | F5: 0 | G5: 0 | H5: 0 | I5: 0 | J5: 0 | K5: 0 | L5: 0 | M5: 0 | N5: 0 | O5: 0 | P5: 0 | Q5: 0 | R5: 0 | S5: 0 | T5: 0 | U5: 0 | V5: 0 | W5: 0 | X5: 0 | Y5: 0 | Z5: 0 | AA5: 0 | AB5: 0 | AC5: 0 | AD5: 0 | AE5: 0 | AF5: 0 | AG5: 0 | AH5: 0 | AI5: 0 | AJ5: 0 | AK5: CARD R&D Project | AL5: NL-C-CRD-001
A6: 6* Lignite to disel cap PRJ NL-C-CRD-002 | B6: 3987309 | C6: 3987309 | D6: 0 | E6: 3987309 | F6: 0 | G6: 3987309 | H6: 3987309 | I6: 0 | J6: 3987309 | K6: 0 | L6: 0 | M6: 0 | N6: 0 | O6: 0 | P6: 0 | Q6: 0 | R6: 0 | S6: 0 | T6: 0 | U6: 0 | V6: 0 | W6: 0 | X6: 0 | Y6: 0 | Z6: 0 | AA6: 0 | AB6: 0 | AC6: 0 | AD6: 0 | AE6: 0 | AF6: 3987309 | AG6: 3987309 | AH6: 0 | AI6: 3987309 | AJ6: 0 | AK6: Lignite to disel cap | AL6: NL-C-CRD-002 | AM6: 6* PRJ NL-C-CRD-002 Lignite to disel cap | AN6: 5945634 | AO6: 3987309 | AP6: 1958325 | AQ6: 32.9 | AR6: 5945634 | AS6: 3987309 | AT6: 1958325 | AU6: 32.9 | AV6: 0 | AW6: 0 | AX6: 0 | AY6: 0 | AZ6: 0 | BA6: 0 | BB6: 0 | BC6: 0 | BD6: 0 | BE6: 0 | BF6: 0 | BG6: 0 | BH6: 0 | BI6: 0 | BJ6: 0 | BK6: 0 | BL6: 5945634 | BM6: 3987309 | BN6: 1958325 | BO6: 32.9 | BP6: Lignite to disel cap
A7: 6* CARD-IITM-Developmen PRJ NL-C-CRD-003 | B7: 13294999 | C7: 3679142.1 | D7: 9615856.8 | E7: 13294999 | F7: 0 | G7: 13294999 | H7: 3679142.1 | I7: 9615856.8 | J7: 13294999 | K7: 0 | L7: 0 | M7: 0 | N7: 0 | O7: 0 | P7: 0 | Q7: 0 | R7: 0 | S7: 0 | T7: 0 | U7: 0 | V7: 0 | W7: 0 | X7: 0 | Y7: 0 | Z7: 0 | AA7: 0 | AB7: 0 | AC7: 0 | AD7: 0 | AE7: 0 | AF7: 13294999 | AG7: 3679142.1 | AH7: 9615856.8 | AI7: 13294999 | AJ7: 0 | AK7: CARD-IITM-Developmen | AL7: NL-C-CRD-003 | AM7: 6* PRJ NL-C-CRD-003 CARD-IITM-Developmen | AN7: 18295400 | AO7: 3679142 | AP7: 14616258 | AQ7: 79.9 | AR7: 18295400 | AS7: 3679142 | AT7: 14616258 | AU7: 79.9 | AV7: 0 | AW7: 0 | AX7: 0 | AY7: 0 | AZ7: 0 | BA7: 0 | BB7: 0 | BC7: 0 | BD7: 0 | BE7: 0 | BF7: 0 | BG7: 0 | BH7: 0 | BI7: 0 | BJ7: 0 | BK7: 0 | BL7: 18295400 | BM7: 3679142 | BN7: 14616258 | BO7: 79.9 | BP7: CARD-IITM-Developmen
A8: 6* CAPEX PROJECT FOR CA PRJ NL-C-CRD-004 | B8: 8.0681444e+08 | C8: 3.6219046e+08 | D8: 2.4664061e+08 | E8: 6.0883108e+08 | F8: 1.9798336e+08 | G8: 2.4180404e+08 | H8: 2.4180404e+08 | I8: 8813116 | J8: 2.5061716e+08 | K8: -8813116 | L8: 5.650104e+08 | M8: 1.2038642e+08 | N8: 2.3124675e+08 | O8: 3.5163317e+08 | P8: 2.1337722e+08 | Q8: 0 | R8: 0 | S8: 6580745.8 | T8: 6580745.8 | U8: -6580745.8 | V8: 0 | W8: 0 | X8: 0 | Y8: 0 | Z8: 0 | AA8: 0 | AB8: 0 | AC8: 0 | AD8: 0 | AE8: 0 | AF8: 8.0681444e+08 | AG8: 3.6219046e+08 | AH8: 2.4664061e+08 | AI8: 6.0883108e+08 | AJ8: 1.9798336e+08 | AK8: CAPEX PROJECT FOR CA | AL8: NL-C-CRD-004 | AM8: 6* PRJ NL-C-CRD-004 CAPEX PROJECT FOR CA | AN8: 718500000 | AO8: 362190463 | AP8: 356309537 | AQ8: 49.6 | AR8: 718500000 | AS8: 241804043 | AT8: 476695957 | AU8: 66.3 | AV8: 0 | AW8: 120386420 | AX8: -120386420 | AY8: 0 | AZ8: 0 | BA8: 0 | BB8: 0 | BC8: 0 | BD8: 0 | BE8: 0 | BF8: 0 | BG8: 0 | BH8: 0 | BI8: 0 | BJ8: 0 | BK8: 0 | BL8: 718500000 | BM8: 362190463 | BN8: 356309537 | BO8: 49.6 | BP8: CAPEX PROJECT FOR CA
A9: 6* Khavda Solar Power P PRJ NL-C-KSP-001 | B9: 398300.04 | C9: 375240 | D9: 23060.04 | E9: 398300.04 | F9: 0 | G9: 375240 | H9: 375240 | I9: 0 | J9: 375240 | K9: 0 | L9: 23060.04 | M9: 0 | N9: 23060.04 | O9: 23060.04 | P9: 0 | Q9: 0 | R9: 0 | S9: 0 | T9: 0 | U9: 0 | V9: 0 | W9: 0 | X9: 0 | Y9: 0 | Z9: 0 | AA9: 0 | AB9: 0 | AC9: 0 | AD9: 0 | AE9: 0 | AF9: 398300.04 | AG9: 375240 | AH9: 23060.04 | AI9: 398300.04 | AJ9: 0 | AK9: Khavda Solar Power P | AL9: NL-C-KSP-001 | AM9: 6* PRJ NL-C-KSP-001 Khavda Solar Power P | AN9: 33358500000 | AO9: 375240 | AP9: 33358124760 | AQ9: 100 | AR9: 33358500000 | AS9: 375240 | AT9: 33358124760 | AU9: 100 | AV9: 0 | AW9: 0 | AX9: 0 | AY9: 0 | AZ9: 0 | BA9: 0 | BB9: 0 | BC9: 0 | BD9: 0 | BE9: 0 | BF9: 0 | BG9: 0 | BH9: 0 | BI9: 0 | BJ9: 0 | BK9: 0 | BL9: 33358500000 | BM9: 375240 | BN9: 33358124760 | BO9: 100 | BP9: Khavda Solar Power P
A10: 6* Land Acquisiton Plan PRJ NL-C-LAQ-001 | B10: 5.4160222e+09 | C10: 3.7048729e+09 | D10: 68131781 | E10: 3.7730047e+09 | F10: 1.6430175e+09 | G10: 2374299156 | H10: 2374299156 | I10: 0 | J10: 2374299156 | K10: 0 | L10: 3.0417231e+09 | M10: 1.3305738e+09 | N10: 68131781 | O10: 1.3987056e+09 | P10: 1.6430175e+09 | Q10: 0 | R10: 0 | S10: 0 | T10: 0 | U10: 0 | V10: 0 | W10: 0 | X10: 0 | Y10: 0 | Z10: 0 | AA10: 0 | AB10: 0 | AC10: 0 | AD10: 0 | AE10: 0 | AF10: 5.4160222e+09 | AG10: 3.7048729e+09 | AH10: 68131781 | AI10: 3.7730047e+09 | AJ10: 1.6430175e+09 | AK10: Land Acquisiton Plan | AL10: NL-C-LAQ-001 | AM10: 6* PRJ NL-C-LAQ-001 Land Acquisiton Plan | AN10: 1400000000 | AO10: 3704872940 | AP10: -2304872940 | AQ10: -164.6 | AR10: 0 | AS10: 2374299156 | AT10: -2374299156 | AU10: 0 | AV10: 1400000000 | AW10: 1330573784 | AX10: 69426216 | AY10: 5 | AZ10: 0 | BA10: 0 | BB10: 0 | BC10: 0 | BD10: 0 | BE10: 0 | BF10: 0 | BG10: 0 | BH10: 0 | BI10: 0 | BJ10: 0 | BK10: 0 | BL10: 1400000000 | BM10: 3704872940 | BN10: -2304872940 | BO10: -164.6 | BP10: Land Acquisiton Plan
A11: 6* EXPANSION OF MINE-IA PRJ NL-C-MIA-001 | B11: 8.8952203e+08 | C11: 6.9805587e+08 | D11: 1.3365458e+08 | E11: 8.3171045e+08 | F11: 57811579 | G11: 3.998401e+08 | H11: 3.9960629e+08 | I11: 0 | J11: 3.9960629e+08 | K11: 233808.46 | L11: 4.8968193e+08 | M11: 2.9844958e+08 | N11: 1.2065071e+08 | O11: 4.1910029e+08 | P11: 70581637 | Q11: 0 | R11: 0 | S11: 13003867 | T11: 13003867 | U11: -13003867 | V11: 0 | W11: 0 | X11: 0 | Y11: 0 | Z11: 0 | AA11: 0 | AB11: 0 | AC11: 0 | AD11: 0 | AE11: 0 | AF11: 8.8952203e+08 | AG11: 6.9805587e+08 | AH11: 1.3365458e+08 | AI11: 8.3171045e+08 | AJ11: 57811579 | AK11: EXPANSION OF MINE-IA | AL11: NL-C-MIA-001 | AM11: 6* PRJ NL-C-MIA-001 EXPANSION OF MINE-IA | AN11: 359054495 | AO11: 698055871 | AP11: -339001376 | AQ11: -94.4 | AR11: 325589555 | AS11: 399606292 | AT11: -74016737 | AU11: -22.7 | AV11: 33464940 | AW11: 298449579 | AX11: -264984639 | AY11: -791.8 | AZ11: 0 | BA11: 0 | BB11: 0 | BC11: 0 | BD11: 0 | BE11: 0 | BF11: 0 | BG11: 0 | BH11: 0 | BI11: 0 | BJ11: 0 | BK11: 0 | BL11: 359054495 | BM11: 698055871 | BN11: -339001376 | BO11: -94.4 | BP11: EXPANSION OF MINE-IA
A12: 6* Mine 1 Capex Project PRJ NL-C-MN1-001 | B12: 0 | C12: 0 | D12: 0 | E12: 0 | F12: 0 | G12: 0 | H12: 0 | I12: 0 | J12: 0 | K12: 0 | L12: 0 | M12: 0 | N12: 0 | O12: 0 | P12: 0 | Q12: 0 | R12: 0 | S12: 0 | T12: 0 | U12: 0 | V12: 0 | W12: 0 | X12: 0 | Y12: 0 | Z12: 0 | AA12: 0 | AB12: 0 | AC12: 0 | AD12: 0 | AE12: 0 | AF12: 0 | AG12: 0 | AH12: 0 | AI12: 0 | AJ12: 0 | AK12: Mine 1 Capex Project | AL12: NL-C-MN1-001 | AM12: 6* PRJ NL-C-MN1-001 Mine 1 Capex Project | AN12: 3390000000 | AO12: 0 | AP12: 3390000000 | AQ12: 100 | AR12: 3390000000 | AS12: 0 | AT12: 3390000000 | AU12: 100 | AV12: 0 | AW12: 0 | AX12: 0 | AY12: 0 | AZ12: 0 | BA12: 0 | BB12: 0 | BC12: 0 | BD12: 0 | BE12: 0 | BF12: 0 | BG12: 0 | BH12: 0 | BI12: 0 | BJ12: 0 | BK12: 0 | BL12: 3390000000 | BM12: 0 | BN12: 3390000000 | BO12: 100 | BP12: Mine 1 Capex Project
A13: 6* Mines III Capex Proj PRJ NL-C-MN3-001 | B13: 85900 | C13: 85892.2 | D13: 0 | E13: 85892.2 | F13: 7.8 | G13: 0 | H13: 0 | I13: 0 | J13: 0 | K13: 0 | L13: 85900 | M13: 85892.2 | N13: 0 | O13: 85892.2 | P13: 7.8 | Q13: 0 | R13: 0 | S13: 0 | T13: 0 | U13: 0 | V13: 0 | W13: 0 | X13: 0 | Y13: 0 | Z13: 0 | AA13: 0 | AB13: 0 | AC13: 0 | AD13: 0 | AE13: 0 | AF13: 85900 | AG13: 85892.2 | AH13: 0 | AI13: 85892.2 | AJ13: 7.8 | AK13: Mines III Capex Proj | AL13: NL-C-MN3-001 | AM13: 6* PRJ NL-C-MN3-001 Mines III Capex Proj | AN13: 37557200000 | AO13: 85892 | AP13: 37557114108 | AQ13: 100 | AR13: 37557200000 | AS13: 0 | AT13: 37557200000 | AU13: 100 | AV13: 0 | AW13: 85892 | AX13: -85892 | AY13: 0 | AZ13: 0 | BA13: 0 | BB13: 0 | BC13: 0 | BD13: 0 | BE13: 0 | BF13: 0 | BG13: 0 | BH13: 0 | BI13: 0 | BJ13: 0 | BK13: 0 | BL13: 37557200000 | BM13: 85892 | BN13: 37557114108 | BO13: 100 | BP13: Mines III Capex Proj
A14: 6* Talabira II & III OC PRJ NL-C-MTL-001 | B14: 1640000000 | C14: 2.9246923e+09 | D14: 8.2433552e+08 | E14: 3.7490278e+09 | F14: -2.1090278e+09 | G14: 1640000000 | H14: 2.95219e+09 | I14: 8.2419552e+08 | J14: 3.7763855e+09 | K14: -2.1363855e+09 | L14: 0 | M14: -27497693 | N14: 0 | O14: -27497693 | P14: 27497693 | Q14: 0 | R14: 0 | S14: 140000.01 | T14: 140000.01 | U14: -140000.01 | V14: 0 | W14: 0 | X14: 0 | Y14: 0 | Z14: 0 | AA14: 0 | AB14: 0 | AC14: 0 | AD14: 0 | AE14: 0 | AF14: 1640000000 | AG14: 2.9246923e+09 | AH14: 8.2433552e+08 | AI14: 3.7490278e+09 | AJ14: -2.1090278e+09 | AK14: Talabira II & III OC | AL14: NL-C-MTL-001 | AM14: 6* PRJ NL-C-MTL-001 Talabira II & III OC | AN14: 790000000 | AO14: 2924692278 | AP14: -2134692278 | AQ14: -270.2 | AR14: 790000000 | AS14: 2952189971 | AT14: -2162189971 | AU14: -273.7 | AV14: 0 | AW14: -27497693 | AX14: 27497693 | AY14: 0 | AZ14: 0 | BA14: 0 | BB14: 0 | BC14: 0 | BD14: 0 | BE14: 0 | BF14: 0 | BG14: 0 | BH14: 0 | BI14: 0 | BJ14: 0 | BK14: 0 | BL14: 790000000 | BM14: 2924692278 | BN14: -2134692278 | BO14: -270.2 | BP14: Talabira II & III OC
A15: 6* Talabira II & III OC PRJ NL-C-MTL-002 | B15: 3.2296441e+09 | C15: 4.7821153e+08 | D15: 1.3806956e+09 | E15: 1.8589072e+09 | F15: 1.370737e+09 | G15: 1.0477658e+08 | H15: 93485870 | I15: 0 | J15: 93485870 | K15: 11290713 | L15: 3.1248676e+09 | M15: 3.8472566e+08 | N15: 1.3654743e+09 | O15: 1.7502e+09 | P15: 1.3746676e+09 | Q15: 0 | R15: 0 | S15: 15221329 | T15: 15221329 | U15: -15221329 | V15: 0 | W15: 0 | X15: 0 | Y15: 0 | Z15: 0 | AA15: 0 | AB15: 0 | AC15: 0 | AD15: 0 | AE15: 0 | AF15: 3.2296441e+09 | AG15: 4.7821153e+08 | AH15: 1.3806956e+09 | AI15: 1.8589072e+09 | AJ15: 1.370737e+09 | AK15: Talabira II & III OC | AL15: NL-C-MTL-002 | AM15: 6* PRJ NL-C-MTL-002 Talabira II & III OC | AN15: 3500000000 | AO15: 478211532 | AP15: 3021788468 | AQ15: 86.3 | AR15: 1500000000 | AS15: 93485870 | AT15: 1406514130 | AU15: 93.8 | AV15: 2000000000 | AW15: 384725662 | AX15: 1615274338 | AY15: 80.8 | AZ15: 0 | BA15: 0 | BB15: 0 | BC15: 0 | BD15: 0 | BE15: 0 | BF15: 0 | BG15: 0 | BH15: 0 | BI15: 0 | BJ15: 0 | BK15: 0 | BL15: 2700000000 | BM15: 478211532 | BN15: 2221788468 | BO15: 82.3 | BP15: Talabira II & III OC
A16: 6* NNTPP CAPEX PROJECT PRJ NL-C-NNT-001 | B16: 2120002000 | C16: 8.3684787e+08 | D16: 1.0860058e+09 | E16: 1.9228537e+09 | F16: 1.971483e+08 | G16: 8.3649597e+08 | H16: 8.3164968e+08 | I16: 0 | J16: 8.3164968e+08 | K16: 4846283.9 | L16: 1.283506e+09 | M16: 5198186.4 | N16: 1.0860058e+09 | O16: 1.091204e+09 | P16: 1.9230201e+08 | Q16: 0 | R16: 0 | S16: 0 | T16: 0 | U16: 0 | V16: 0 | W16: 0 | X16: 0 | Y16: 0 | Z16: 0 | AA16: 0 | AB16: 0 | AC16: 0 | AD16: 0 | AE16: 0 | AF16: 2120002000 | AG16: 8.3684787e+08 | AH16: 1.0860058e+09 | AI16: 1.9228537e+09 | AJ16: 1.971483e+08 | AK16: NNTPP CAPEX PROJECT | AL16: NL-C-NNT-001 | AM16: 6* PRJ NL-C-NNT-001 NNTPP CAPEX PROJECT | AN16: 3787793152 | AO16: 836847870 | AP16: 2950945281 | AQ16: 77.9 | AR16: 3787793152 | AS16: 831649684 | AT16: 2956143468 | AU16: 78 | AV16: 0 | AW16: 5198186 | AX16: -5198186 | AY16: 0 | AZ16: 0 | BA16: 0 | BB16: 0 | BC16: 0 | BD16: 0 | BE16: 0 | BF16: 0 | BG16: 0 | BH16: 0 | BI16: 0 | BJ16: 0 | BK16: 0 | BL16: 11092690297 | BM16: 836847870 | BN16: 10255842426 | BO16: 92.5 | BP16: NNTPP CAPEX PROJECT
A17: 6* NNTPP Flue Gas Desul PRJ NL-C-NNT-002 | B17: 1.0651836e+10 | C17: 9.4673189e+09 | D17: 1.122297e+09 | E17: 1.0589616e+10 | F17: 62220520 | G17: 6.3930374e+09 | H17: 6.6446558e+09 | I17: 40616473 | J17: 6.6852723e+09 | K17: -2.9223484e+08 | L17: 4.2587989e+09 | M17: 2.8226631e+09 | N17: 1.0816805e+09 | O17: 3.9043436e+09 | P17: 3.5445536e+08 | Q17: 0 | R17: 0 | S17: 0 | T17: 0 | U17: 0 | V17: 0 | W17: 0 | X17: 0 | Y17: 0 | Z17: 0 | AA17: 0 | AB17: 0 | AC17: 0 | AD17: 0 | AE17: 0 | AF17: 1.0651836e+10 | AG17: 9.4673189e+09 | AH17: 1.122297e+09 | AI17: 1.0589616e+10 | AJ17: 62220520 | AK17: NNTPP Flue Gas Desul | AL17: NL-C-NNT-002 | AM17: 6* PRJ NL-C-NNT-002 NNTPP Flue Gas Desul | AN17: 1162278 | AO17: 9467318888 | AP17: -9466156610 | AQ17: -814448.6 | AR17: 1162278 | AS17: 6644655814 | AT17: -6643493536 | AU17: -571592.5 | AV17: 0 | AW17: 2822663073 | AX17: -2822663073 | AY17: 0 | AZ17: 0 | BA17: 0 | BB17: 0 | BC17: 0 | BD17: 0 | BE17: 0 | BF17: 0 | BG17: 0 | BH17: 0 | BI17: 0 | BJ17: 0 | BK17: 0 | BL17: 9148902993 | BM17: 9467318888 | BN17: -318415895 | BO17: -3.5 | BP17: NNTPP Flue Gas Desul
A18: 6* New Patrapara South PRJ NL-C-NPS-001 | B18: 2400000000 | C18: 1.9579273e+09 | D18: 0 | E18: 1.9579273e+09 | F18: 4.4207268e+08 | G18: 0 | H18: 0 | I18: 0 | J18: 0 | K18: 0 | L18: 2400000000 | M18: 1.9579273e+09 | N18: 0 | O18: 1.9579273e+09 | P18: 4.4207268e+08 | Q18: 0 | R18: 0 | S18: 0 | T18: 0 | U18: 0 | V18: 0 | W18: 0 | X18: 0 | Y18: 0 | Z18: 0 | AA18: 0 | AB18: 0 | AC18: 0 | AD18: 0 | AE18: 0 | AF18: 2400000000 | AG18: 1.9579273e+09 | AH18: 0 | AI18: 1.9579273e+09 | AJ18: 4.4207268e+08 | AK18: New Patrapara South | AL18: NL-C-NPS-001 | AM18: 6* PRJ NL-C-NPS-001 New Patrapara South | AN18: 4805000000 | AO18: 1957927320 | AP18: 2847072680 | AQ18: 59.3 | AR18: 0 | AS18: 0 | AT18: 0 | AU18: 0 | AV18: 4805000000 | AW18: 1957927320 | AX18: 2847072680 | AY18: 59.3 | AZ18: 0 | BA18: 0 | BB18: 0 | BC18: 0 | BD18: 0 | BE18: 0 | BF18: 0 | BG18: 0 | BH18: 0 | BI18: 0 | BJ18: 0 | BK18: 0 | BL18: 4805000000 | BM18: 1957927320 | BN18: 2847072680 | BO18: 59.3 | BP18: New Patrapara South
A19: 6* IREDA-CPSU Scheme Ph PRJ NL-C-PBD-001 | B19: 60180000 | C19: 0 | D19: 0 | E19: 0 | F19: 60180000 | G19: 0 | H19: 0 | I19: 0 | J19: 0 | K19: 0 | L19: 60180000 | M19: 0 | N19: 0 | O19: 0 | P19: 60180000 | Q19: 0 | R19: 0 | S19: 0 | T19: 0 | U19: 0 | V19: 0 | W19: 0 | X19: 0 | Y19: 0 | Z19: 0 | AA19: 0 | AB19: 0 | AC19: 0 | AD19: 0 | AE19: 0 | AF19: 60180000 | AG19: 0 | AH19: 0 | AI19: 0 | AJ19: 60180000 | AK19: IREDA-CPSU Scheme Ph | AL19: NL-C-PBD-001
A20: 6* Neyveli 2x65 MW Sola PRJ NL-C-PBD-002 | B20: 10669830 | C20: 10289078 | D20: 380751.03 | E20: 10669829 | F20: 0.96 | G20: 0 | H20: 10289078 | I20: 0 | J20: 10289078 | K20: -10289078 | L20: 10669830 | M20: 0 | N20: 380751.03 | O20: 380751.03 | P20: 10289079 | Q20: 0 | R20: 0 | S20: 0 | T20: 0 | U20: 0 | V20: 0 | W20: 0 | X20: 0 | Y20: 0 | Z20: 0 | AA20: 0 | AB20: 0 | AC20: 0 | AD20: 0 | AE20: 0 | AF20: 10669830 | AG20: 10289078 | AH20: 380751.03 | AI20: 10669829 | AJ20: 0.96 | AK20: Neyveli 2x65 MW Sola | AL20: NL-C-PBD-002 | AM20: 6* PRJ NL-C-PBD-002 Neyveli 2x65 MW Sola | AN20: 6669830 | AO20: 10289078 | AP20: -3619248 | AQ20: -54.3 | AR20: 6669830 | AS20: 10289078 | AT20: -3619248 | AU20: -54.3 | AV20: 0 | AW20: 0 | AX20: 0 | AY20: 0 | AZ20: 0 | BA20: 0 | BB20: 0 | BC20: 0 | BD20: 0 | BE20: 0 | BF20: 0 | BG20: 0 | BH20: 0 | BI20: 0 | BJ20: 0 | BK20: 0 | BL20: 10669830 | BM20: 10289078 | BN20: 380752 | BO20: 3.6 | BP20: Neyveli 2x65 MW Sola
A21: 6* Solar 10 MW Power Pr PRJ NL-C-SOL-001 | B21: 175000000 | C21: 4.5359629e+08 | D21: 1.4450137e+08 | E21: 5.9809767e+08 | F21: -4.2309767e+08 | G21: 175000000 | H21: 4.5359629e+08 | I21: 0 | J21: 4.5359629e+08 | K21: -2.7859629e+08 | L21: 0 | M21: 0 | N21: 1.4450137e+08 | O21: 1.4450137e+08 | P21: -1.4450137e+08 | Q21: 0 | R21: 0 | S21: 0 | T21: 0 | U21: 0 | V21: 0 | W21: 0 | X21: 0 | Y21: 0 | Z21: 0 | AA21: 0 | AB21: 0 | AC21: 0 | AD21: 0 | AE21: 0 | AF21: 175000000 | AG21: 4.5359629e+08 | AH21: 1.4450137e+08 | AI21: 5.9809767e+08 | AJ21: -4.2309767e+08 | AK21: Solar 10 MW Power Pr | AL21: NL-C-SOL-001 | AM21: 6* PRJ NL-C-SOL-001 Solar 10 MW Power Pr | AN21: 0 | AO21: 453596292 | AP21: -453596292 | AQ21: 0 | AR21: 0 | AS21: 453596292 | AT21: -453596292 | AU21: 0 | AV21: 0 | AW21: 0 | AX21: 0 | AY21: 0 | AZ21: 0 | BA21: 0 | BB21: 0 | BC21: 0 | BD21: 0 | BE21: 0 | BF21: 0 | BG21: 0 | BH21: 0 | BI21: 0 | BJ21: 0 | BK21: 0 | BL21: 0 | BM21: 453596292 | BN21: -453596292 | BO21: 0 | BP21: Solar 10 MW Power Pr
A22: 6* Solar 50 MW in Mine PRJ NL-C-SOL-002 | B22: 1807443528 | C22: 1.2545294e+09 | D22: 5.5289682e+08 | E22: 1.8074262e+09 | F22: 17288.72 | G22: 850544 | H22: 850544 | I22: 0 | J22: 850544 | K22: 0 | L22: 1806592984 | M22: 1.2536789e+09 | N22: 5.5289682e+08 | O22: 1.8065757e+09 | P22: 17288.72 | Q22: 0 | R22: 0 | S22: 0 | T22: 0 | U22: 0 | V22: 0 | W22: 0 | X22: 0 | Y22: 0 | Z22: 0 | AA22: 0 | AB22: 0 | AC22: 0 | AD22: 0 | AE22: 0 | AF22: 1807443528 | AG22: 1.2545294e+09 | AH22: 5.5289682e+08 | AI22: 1.8074262e+09 | AJ22: 17288.72 | AK22: Solar 50 MW in Mine | AL22: NL-C-SOL-002 | AM22: 6* PRJ NL-C-SOL-002 Solar 50 MW in Mine | AN22: 2951200000 | AO22: 1254529420 | AP22: 1696670580 | AQ22: 57.5 | AR22: 2951200000 | AS22: 850544 | AT22: 2950349456 | AU22: 100 | AV22: 0 | AW22: 1253678876 | AX22: -1253678876 | AY22: 0 | AZ22: 0 | BA22: 0 | BB22: 0 | BC22: 0 | BD22: 0 | BE22: 0 | BF22: 0 | BG22: 0 | BH22: 0 | BI22: 0 | BJ22: 0 | BK22: 0 | BL22: 2951200000 | BM22: 1254529420 | BN22: 1696670580 | BO22: 57.5 | BP22: Solar 50 MW in Mine
A23: 6* 200 MW Solar Power G PRJ NL-C-SOL-003 | B23: 522382455 | C23: 1420211.2 | D23: 902748.88 | E23: 2322960 | F23: 5.2005949e+08 | G23: 0 | H23: 0 | I23: 0 | J23: 0 | K23: 0 | L23: 522382455 | M23: 1420211.2 | N23: 902748.88 | O23: 2322960 | P23: 5.2005949e+08 | Q23: 0 | R23: 0 | S23: 0 | T23: 0 | U23: 0 | V23: 0 | W23: 0 | X23: 0 | Y23: 0 | Z23: 0 | AA23: 0 | AB23: 0 | AC23: 0 | AD23: 0 | AE23: 0 | AF23: 522382455 | AG23: 1420211.2 | AH23: 902748.88 | AI23: 2322960 | AJ23: 5.2005949e+08 | AK23: 200 MW Solar Power G | AL23: NL-C-SOL-003 | AM23: 6* PRJ NL-C-SOL-003 200 MW Solar Power G | AN23: 12138960364 | AO23: 1420211 | AP23: 12137540152 | AQ23: 100 | AR23: 0 | AS23: 0 | AT23: 0 | AU23: 0 | AV23: 12138960364 | AW23: 1420211 | AX23: 12137540152 | AY23: 100 | AZ23: 0 | BA23: 0 | BB23: 0 | BC23: 0 | BD23: 0 | BE23: 0 | BF23: 0 | BG23: 0 | BH23: 0 | BI23: 0 | BJ23: 0 | BK23: 0 | BL23: 12138960364 | BM23: 1420211 | BN23: 12137540152 | BO23: 100 | BP23: 200 MW Solar Power G
A24: 6* 100 MW SOLAR (HYBRID PRJ NL-C-SOL-004 | B24: 1350000000 | C24: 1176000 | D24: 574000 | E24: 1750000 | F24: 1348250000 | G24: 0 | H24: 0 | I24: 0 | J24: 0 | K24: 0 | L24: 1350000000 | M24: 1176000 | N24: 574000 | O24: 1750000 | P24: 1348250000 | Q24: 0 | R24: 0 | S24: 0 | T24: 0 | U24: 0 | V24: 0 | W24: 0 | X24: 0 | Y24: 0 | Z24: 0 | AA24: 0 | AB24: 0 | AC24: 0 | AD24: 0 | AE24: 0 | AF24: 1350000000 | AG24: 1176000 | AH24: 574000 | AI24: 1750000 | AJ24: 1348250000 | AK24: 100 MW SOLAR (HYBRID | AL24: NL-C-SOL-004 | AM24: 6* PRJ NL-C-SOL-004 100 MW SOLAR (HYBRID | AN24: 0 | AO24: 1176000 | AP24: -1176000 | AQ24: 0 | AR24: 0 | AS24: 0 | AT24: 0 | AU24: 0 | AV24: 0 | AW24: 1176000 | AX24: -1176000 | AY24: 0 | AZ24: 0 | BA24: 0 | BB24: 0 | BC24: 0 | BD24: 0 | BE24: 0 | BF24: 0 | BG24: 0 | BH24: 0 | BI24: 0 | BJ24: 0 | BK24: 0 | BL24: 0 | BM24: 1176000 | BN24: -1176000 | BO24: 0 | BP24: 100 MW SOLAR (HYBRID
A25: 6* TPS2 Second Expansio PRJ NL-C-T22-001 | B25: 37386465 | C25: 45813963 | D25: 1018104 | E25: 46832067 | F25: -9445602 | G25: 28694848 | H25: 38047111 | I25: 0 | J25: 38047111 | K25: -9352262.8 | L25: 8691616.8 | M25: 7766852 | N25: 1018104 | O25: 8784956 | P25: -93339.24 | Q25: 0 | R25: 0 | S25: 0 | T25: 0 | U25: 0 | V25: 0 | W25: 0 | X25: 0 | Y25: 0 | Z25: 0 | AA25: 0 | AB25: 0 | AC25: 0 | AD25: 0 | AE25: 0 | AF25: 37386465 | AG25: 45813963 | AH25: 1018104 | AI25: 46832067 | AJ25: -9445602 | AK25: TPS2 Second Expansio | AL25: NL-C-T22-001 | AM25: 6* PRJ NL-C-T22-001 TPS2 Second Expansio | AN25: 668500000 | AO25: 45813963 | AP25: 622686037 | AQ25: 93.1 | AR25: 668500000 | AS25: 38047111 | AT25: 630452889 | AU25: 94.3 | AV25: 0 | AW25: 7766852 | AX25: -7766852 | AY25: 0 | AZ25: 0 | BA25: 0 | BB25: 0 | BC25: 0 | BD25: 0 | BE25: 0 | BF25: 0 | BG25: 0 | BH25: 0 | BI25: 0 | BJ25: 0 | BK25: 0 | BL25: 668500000 | BM25: 45813963 | BN25: 622686037 | BO25: 93.1 | BP25: TPS2 Second Expansio
A26: 6* Performance Improvem PRJ NL-C-T2E-001 | B26: 1058534096 | C26: 7.8493291e+08 | D26: 2.1141268e+08 | E26: 9.9634559e+08 | F26: 62188509 | G26: 5.4729204e+08 | H26: 5.4729204e+08 | I26: 0 | J26: 5.4729204e+08 | K26: 0 | L26: 5.1124205e+08 | M26: 2.3764087e+08 | N26: 2.1141268e+08 | O26: 4.4905354e+08 | P26: 62188509 | Q26: 0 | R26: 0 | S26: 0 | T26: 0 | U26: 0 | V26: 0 | W26: 0 | X26: 0 | Y26: 0 | Z26: 0 | AA26: 0 | AB26: 0 | AC26: 0 | AD26: 0 | AE26: 0 | AF26: 1058534096 | AG26: 7.8493291e+08 | AH26: 2.1141268e+08 | AI26: 9.9634559e+08 | AJ26: 62188509 | AK26: Performance Improvem | AL26: NL-C-T2E-001 | AM26: 6* PRJ NL-C-T2E-001 Performance Improvem | AN26: 1058534096 | AO26: 784932908 | AP26: 273601188 | AQ26: 25.8 | AR26: 1058534096 | AS26: 547292043 | AT26: 511242053 | AU26: 48.3 | AV26: 0 | AW26: 237640865 | AX26: -237640865 | AY26: 0 | AZ26: 0 | BA26: 0 | BB26: 0 | BC26: 0 | BD26: 0 | BE26: 0 | BF26: 0 | BG26: 0 | BH26: 0 | BI26: 0 | BJ26: 0 | BK26: 0 | BL26: 1058534096 | BM26: 784932908 | BN26: 273601188 | BO26: 25.8 | BP26: Performance Improvem
A27: 6* Mini Smart City PRJ NL-C-TAA-001 | B27: 173380000 | C27: 6139687.5 | D27: 5321062.5 | E27: 11460750 | F27: 161919250 | G27: 2455875 | H27: 2455875 | I27: 0 | J27: 2455875 | K27: 0 | L27: 170924125 | M27: 3683812.5 | N27: 5321062.5 | O27: 9004875 | P27: 161919250 | Q27: 0 | R27: 0 | S27: 0 | T27: 0 | U27: 0 | V27: 0 | W27: 0 | X27: 0 | Y27: 0 | Z27: 0 | AA27: 0 | AB27: 0 | AC27: 0 | AD27: 0 | AE27: 0 | AF27: 173380000 | AG27: 6139687.5 | AH27: 5321062.5 | AI27: 11460750 | AJ27: 161919250 | AK27: Mini Smart City | AL27: NL-C-TAA-001 | AM27: 6* PRJ NL-C-TAA-001 Mini Smart City | AN27: 6720 | AO27: 6139688 | AP27: -6132968 | AQ27: -91271.2 | AR27: 6720 | AS27: 2455875 | AT27: -2449156 | AU27: -36448.5 | AV27: 0 | AW27: 3683813 | AX27: -3683813 | AY27: 0 | AZ27: 0 | BA27: 0 | BB27: 0 | BC27: 0 | BD27: 0 | BE27: 0 | BF27: 0 | BG27: 0 | BH27: 0 | BI27: 0 | BJ27: 0 | BK27: 0 | BL27: 6551 | BM27: 6139688 | BN27: -6133137 | BO27: -93624.2 | BP27: Mini Smart City
A28: 6* NLC Talabira Thermal PRJ NL-C-TPP-001 | B28: 4.2282451e+09 | C28: 1.4718109e+09 | D28: 1.3161227e+09 | E28: 2.7879336e+09 | F28: 1.4403115e+09 | G28: 1.0036764e+09 | H28: 1.0048295e+09 | I28: 0 | J28: 1.0048295e+09 | K28: -1153049.4 | L28: 3.2245687e+09 | M28: 4.6698144e+08 | N28: 1.3161227e+09 | O28: 1.7831041e+09 | P28: 1.4414646e+09 | Q28: 0 | R28: 0 | S28: 0 | T28: 0 | U28: 0 | V28: 0 | W28: 0 | X28: 0 | Y28: 0 | Z28: 0 | AA28: 0 | AB28: 0 | AC28: 0 | AD28: 0 | AE28: 0 | AF28: 4.2282451e+09 | AG28: 1.4718109e+09 | AH28: 1.3161227e+09 | AI28: 2.7879336e+09 | AJ28: 1.4403115e+09 | AK28: NLC Talabira Thermal | AL28: NL-C-TPP-001 | AM28: 6* PRJ NL-C-TPP-001 NLC Talabira Thermal | AN28: 12542700000 | AO28: 1471810906 | AP28: 11070889094 | AQ28: 88.3 | AR28: 11542700000 | AS28: 1004829466 | AT28: 10537870534 | AU28: 91.3 | AV28: 1000000000 | AW28: 466981440 | AX28: 533018560 | AY28: 53.3 | AZ28: 0 | BA28: 0 | BB28: 0 | BC28: 0 | BD28: 0 | BE28: 0 | BF28: 0 | BG28: 0 | BH28: 0 | BI28: 0 | BJ28: 0 | BK28: 0 | BL28: 11542700000 | BM28: 1471810906 | BN28: 10070889094 | BO28: 87.2 | BP28: NLC Talabira Thermal
A29: 6* NLC TTPP Main Packag PRJ NL-C-TPP-002 | B29: 6029690000 | C29: 1529689520 | D29: 4.4659793e+09 | E29: 5.9956688e+09 | F29: 34021226 | G29: 1529689520 | H29: 1529689520 | I29: 0 | J29: 1529689520 | K29: 0 | L29: 4500000480 | M29: 0 | N29: 4.4659793e+09 | O29: 4.4659793e+09 | P29: 34021226 | Q29: 0 | R29: 0 | S29: 0 | T29: 0 | U29: 0 | V29: 0 | W29: 0 | X29: 0 | Y29: 0 | Z29: 0 | AA29: 0 | AB29: 0 | AC29: 0 | AD29: 0 | AE29: 0 | AF29: 6029690000 | AG29: 1529689520 | AH29: 4.4659793e+09 | AI29: 5.9956688e+09 | AJ29: 34021226 | AK29: NLC TTPP Main Packag | AL29: NL-C-TPP-002 | AM29: 6* PRJ NL-C-TPP-002 NLC TTPP Main Packag | AN29: 0 | AO29: 1529689520 | AP29: -1529689520 | AQ29: 0 | AR29: 0 | AS29: 1529689520 | AT29: -1529689520 | AU29: 0 | AV29: 0 | AW29: 0 | AX29: 0 | AY29: 0 | AZ29: 0 | BA29: 0 | BB29: 0 | BC29: 0 | BD29: 0 | BE29: 0 | BF29: 0 | BG29: 0 | BH29: 0 | BI29: 0 | BJ29: 0 | BK29: 0 | BL29: 0 | BM29: 1529689520 | BN29: -1529689520 | BO29: 0 | BP29: NLC TTPP Main Packag
A30: 6* TS I Switchyard Modi PRJ NL-C-TS1-001 | B30: 3.1061295e+08 | C30: 2.8340981e+08 | D30: 27197650 | E30: 3.1060746e+08 | F30: 5491.19 | G30: 2.5797312e+08 | H30: 2.5797312e+08 | I30: 0.59 | J30: 2.5797313e+08 | K30: -0.59 | L30: 52639823 | M30: 25436681 | N30: 27197650 | O30: 52634331 | P30: 5491.78 | Q30: 0 | R30: 0 | S30: 0 | T30: 0 | U30: 0 | V30: 0 | W30: 0 | X30: 0 | Y30: 0 | Z30: 0 | AA30: 0 | AB30: 0 | AC30: 0 | AD30: 0 | AE30: 0 | AF30: 3.1061295e+08 | AG30: 2.8340981e+08 | AH30: 27197650 | AI30: 3.1060746e+08 | AJ30: 5491.19 | AK30: TS I Switchyard Modi | AL30: NL-C-TS1-001 | AM30: 6* PRJ NL-C-TS1-001 TS I Switchyard Modi | AN30: 307545691 | AO30: 283409806 | AP30: 24135885 | AQ30: 7.8 | AR30: 307545691 | AS30: 257973125 | AT30: 49572566 | AU30: 16.1 | AV30: 0 | AW30: 25436681 | AX30: -25436681 | AY30: 0 | AZ30: 0 | BA30: 0 | BB30: 0 | BC30: 0 | BD30: 0 | BE30: 0 | BF30: 0 | BG30: 0 | BH30: 0 | BI30: 0 | BJ30: 0 | BK30: 0 | BL30: 307545691 | BM30: 283409806 | BN30: 24135885 | BO30: 7.8 | BP30: TS I Switchyard Modi
A31: 6* Wind Turbine Project PRJ NL-C-WND-001 | B31: 23203970 | C31: 18416660 | D31: 4604165 | E31: 23020825 | F31: 183145 | G31: 18416660 | H31: 18416660 | I31: 0 | J31: 18416660 | K31: 0 | L31: 4787310 | M31: 0 | N31: 4604165 | O31: 4604165 | P31: 183145 | Q31: 0 | R31: 0 | S31: 0 | T31: 0 | U31: 0 | V31: 0 | W31: 0 | X31: 0 | Y31: 0 | Z31: 0 | AA31: 0 | AB31: 0 | AC31: 0 | AD31: 0 | AE31: 0 | AF31: 23203970 | AG31: 18416660 | AH31: 4604165 | AI31: 23020825 | AJ31: 183145 | AK31: Wind Turbine Project | AL31: NL-C-WND-001 | AM31: 6* PRJ NL-C-WND-001 Wind Turbine Project | AN31: 0 | AO31: 18416660 | AP31: -18416660 | AQ31: 0 | AR31: 0 | AS31: 18416660 | AT31: -18416660 | AU31: 0 | AV31: 0 | AW31: 0 | AX31: 0 | AY31: 0 | AZ31: 0 | BA31: 0 | BB31: 0 | BC31: 0 | BD31: 0 | BE31: 0 | BF31: 0 | BG31: 0 | BH31: 0 | BI31: 0 | BJ31: 0 | BK31: 0 | BL31: 0 | BM31: 18416660 | BN31: -18416660 | BO31: 0 | BP31: Wind Turbine Project
... A42: 6* Safety Capital Mater PRJ NL-M-SFT-001 | B42: 8766352.1 | C42: 8766352.1 | D42: 0 | E42: 8766352.1 | F42: 0 | G42: 8766352.1 | H42: 8766352.1 | I42: 0 | J42: 8766352.1 | K42: 0 | L42: 0 | M42: 0 | N42: 0 | O42: 0 | P42: 0 | Q42: 0 | R42: 0 | S42: 0 | T42: 0 | U42: 0 | V42: 0 | W42: 0 | X42: 0 | Y42: 0 | Z42: 0 | AA42: 0 | AB42: 0 | AC42: 0 | AD42: 0 | AE42: 0 | AF42: 8766352.1 | AG42: 8766352.1 | AH42: 0 | AI42: 8766352.1 | AJ42: 0 | AK42: Safety Capital Mater | AL42: NL-M-SFT-001 | AM42: 6* PRJ NL-M-SFT-001 Safety Capital Mater | AN42: 30000000 | AO42: 8766352 | AP42: 21233648 | AQ42: 70.8 | AR42: 30000000 | AS42: 8766352 | AT42: 21233648 | AU42: 70.8 | AV42: 0 | AW42: 0 | AX42: 0 | AY42: 0 | AZ42: 0 | BA42: 0 | BB42: 0 | BC42: 0 | BD42: 0 | BE42: 0 | BF42: 0 | BG42: 0 | BH42: 0 | BI42: 0 | BJ42: 0 | BK42: 0 | BL42: 30000000 | BM42: 8766352 | BN42: 21233648 | BO42: 70.8 | BP42: Safety Capital Mater
A43: 6* TPS 1 Exp. Capital M PRJ NL-M-T1E-001 | B43: 40000000 | C43: 0 | D43: 0 | E43: 0 | F43: 40000000 | G43: 0 | H43: 0 | I43: 0 | J43: 0 | K43: 0 | L43: 40000000 | M43: 0 | N43: 0 | O43: 0 | P43: 40000000 | Q43: 0 | R43: 0 | S43: 0 | T43: 0 | U43: 0 | V43: 0 | W43: 0 | X43: 0 | Y43: 0 | Z43: 0 | AA43: 0 | AB43: 0 | AC43: 0 | AD43: 0 | AE43: 0 | AF43: 40000000 | AG43: 0 | AH43: 0 | AI43: 0 | AJ43: 40000000 | AK43: TPS 1 Exp. Capital M | AL43: NL-M-T1E-001
A44: 6* TPS2Exp - Capital Ma PRJ NL-M-T2E-001 | B44: 7.2433133e+08 | C44: 2.8340234e+08 | D44: 2.8077382e+08 | E44: 5.6417616e+08 | F44: 1.6015517e+08 | G44: 1.5388029e+08 | H44: 1.5388029e+08 | I44: 0 | J44: 1.5388029e+08 | K44: 0 | L44: 5.7045103e+08 | M44: 1.2952204e+08 | N44: 2.4132535e+08 | O44: 3.7084739e+08 | P44: 1.9960364e+08 | Q44: 0 | R44: 0 | S44: 39448472 | T44: 39448472 | U44: -39448472 | V44: 0 | W44: 0 | X44: 0 | Y44: 0 | Z44: 0 | AA44: 0 | AB44: 0 | AC44: 0 | AD44: 0 | AE44: 0 | AF44: 7.2433133e+08 | AG44: 2.8340234e+08 | AH44: 2.8077382e+08 | AI44: 5.6417616e+08 | AJ44: 1.6015517e+08 | AK44: TPS2Exp - Capital Ma | AL44: NL-M-T2E-001 | AM44: 6* PRJ NL-M-T2E-001 TPS2Exp - Capital Ma | AN44: 0 | AO44: 283402336 | AP44: -283402336 | AQ44: 0 | AR44: 0 | AS44: 153880293 | AT44: -153880293 | AU44: 0 | AV44: 0 | AW44: 129522043 | AX44: -129522043 | AY44: 0 | AZ44: 0 | BA44: 0 | BB44: 0 | BC44: 0 | BD44: 0 | BE44: 0 | BF44: 0 | BG44: 0 | BH44: 0 | BI44: 0 | BJ44: 0 | BK44: 0 | BL44: 0 | BM44: 283402336 | BN44: -283402336 | BO44: 0 | BP44: TPS2Exp - Capital Ma
AL45: NL-N-BSP-001 | AM45: 6* PRJ NL-N-BSP-001-01 Barsingsar Thermal N | AN45: 2576321000 | AO45: 415436751 | AP45: 2160884249 | AQ45: 83.9 | AR45: 1975171000 | AS45: 22957871 | AT45: 1952213129 | AU45: 98.8 | AV45: 601150000 | AW45: 392478880 | AX45: 208671120 | AY45: 34.7 | AZ45: 0 | BA45: 0 | BB45: 0 | BC45: 0 | BD45: 0 | BE45: 0 | BF45: 0 | BG45: 0 | BH45: 0 | BI45: 0 | BJ45: 0 | BK45: 0 | BL45: 2491321000 | BM45: 415436751 | BN45: 2075884249 | BO45: 83.3 | BP45: -01 Barsingsar Thermal N
A46: 6* Barsingsar Thermal N PRJ NL-N-BSP-001-01 | B46: 1.0681356e+09 | C46: 4.1543675e+08 | D46: 4.8692619e+08 | E46: 9.0236294e+08 | F46: 1.6577265e+08 | G46: 24415486 | H46: 22957871 | I46: 5091198.7 | J46: 28049070 | K46: -3633583.1 | L46: 1.0437201e+09 | M46: 3.9247888e+08 | N46: 4.1925841e+08 | O46: 8.1173729e+08 | P46: 2.3198281e+08 | Q46: 0 | R46: 0 | S46: 62576576 | T46: 62576576 | U46: -62576576 | V46: 0 | W46: 0 | X46: 0 | Y46: 0 | Z46: 0 | AA46: 0 | AB46: 0 | AC46: 0 | AD46: 0 | AE46: 0 | AF46: 1.0681356e+09 | AG46: 4.1543675e+08 | AH46: 4.8692619e+08 | AI46: 9.0236294e+08 | AJ46: 1.6577265e+08 | AK46: Barsingsar Thermal N | AL46: NL-N-BSP-001-01
A47: 6* Central Establishmen PRJ NL-N-CES-001 | B47: 3.2407823e+08 | C47: 2.0196157e+08 | D47: 14700306 | E47: 2.1666187e+08 | F47: 1.0741636e+08 | G47: 3.2407823e+08 | H47: 1.9489121e+08 | I47: 14700306 | J47: 2.0959151e+08 | K47: 1.1448672e+08 | L47: 0 | M47: 7070360.4 | N47: 0 | O47: 7070360.4 | P47: -7070360.4 | Q47: 0 | R47: 0 | S47: 0 | T47: 0 | U47: 0 | V47: 0 | W47: 0 | X47: 0 | Y47: 0 | Z47: 0 | AA47: 0 | AB47: 0 | AC47: 0 | AD47: 0 | AE47: 0 | AF47: 3.7089859e+08 | AG47: 2.0196157e+08 | AH47: 14700306 | AI47: 2.1666187e+08 | AJ47: 1.5423671e+08 | AK47: Central Establishmen | AL47: NL-N-CES-001 | AM47: 6* PRJ NL-N-CES-001 Central Establishmen | AN47: 468116057 | AO47: 201961569 | AP47: 266154488 | AQ47: 56.9 | AR47: 468116057 | AS47: 194891208 | AT47: 273224849 | AU47: 58.4 | AV47: 0 | AW47: 7070360 | AX47: -7070360 | AY47: 0 | AZ47: 0 | BA47: 0 | BB47: 0 | BC47: 0 | BD47: 0 | BE47: 0 | BF47: 0 | BG47: 0 | BH47: 0 | BI47: 0 | BJ47: 0 | BK47: 0 | BL47: 469980138 | BM47: 201961569 | BN47: 268018569 | BO47: 57 | BP47: Central Establishmen
A48: 6* Manager Corporate Of PRJ NL-N-CES-002 | B48: 1767875.5 | C48: 1713150 | D48: 53421 | E48: 1766571 | F48: 1304.51 | G48: 1767875.5 | H48: 1713150 | I48: 53421 | J48: 1766571 | K48: 1304.51 | L48: 0 | M48: 0 | N48: 0 | O48: 0 | P48: 0 | Q48: 0 | R48: 0 | S48: 0 | T48: 0 | U48: 0 | V48: 0 | W48: 0 | X48: 0 | Y48: 0 | Z48: 0 | AA48: 0 | AB48: 0 | AC48: 0 | AD48: 0 | AE48: 0 | AF48: 1767875.5 | AG48: 1713150 | AH48: 53421 | AI48: 1766571 | AJ48: 1304.51 | AK48: Manager Corporate Of | AL48: NL-N-CES-002 | AM48: 6* PRJ NL-N-CES-002 Manager Corporate Of | AN48: 21000000 | AO48: 1713150 | AP48: 19286850 | AQ48: 91.8 | AR48: 21000000 | AS48: 1713150 | AT48: 19286850 | AU48: 91.8 | AV48: 0 | AW48: 0 | AX48: 0 | AY48: 0 | AZ48: 0 | BA48: 0 | BB48: 0 | BC48: 0 | BD48: 0 | BE48: 0 | BF48: 0 | BG48: 0 | BH48: 0 | BI48: 0 | BJ48: 0 | BK48: 0 | BL48: 21000000 | BM48: 1713150 | BN48: 19286850 | BO48: 91.8 | BP48: Manager Corporate Of
A49: 6* CISF Non-Plan CapEx PRJ NL-N-CIS-001 | B49: 19625820 | C49: 1911305 | D49: 4877892 | E49: 6789197 | F49: 12836623 | G49: 1911304.9 | H49: 1911305 | I49: 0 | J49: 1911305 | K49: -0.02 | L49: 17714515 | M49: 0 | N49: 4877892 | O49: 4877892 | P49: 12836623 | Q49: 0 | R49: 0 | S49: 0 | T49: 0 | U49: 0 | V49: 0 | W49: 0 | X49: 0 | Y49: 0 | Z49: 0 | AA49: 0 | AB49: 0 | AC49: 0 | AD49: 0 | AE49: 0 | AF49: 19625820 | AG49: 1911305 | AH49: 4877892 | AI49: 6789197 | AJ49: 12836623 | AK49: CISF Non-Plan CapEx | AL49: NL-N-CIS-001 | AM49: 6* PRJ NL-N-CIS-001 CISF Non-Plan CapEx | AN49: 19113000 | AO49: 1911305 | AP49: 17201695 | AQ49: 90 | AR49: 5713000 | AS49: 1911305 | AT49: 3801695 | AU49: 66.5 | AV49: 13400000 | AW49: 0 | AX49: 13400000 | AY49: 100 | AZ49: 0 | BA49: 0 | BB49: 0 | BC49: 0 | BD49: 0 | BE49: 0 | BF49: 0 | BG49: 0 | BH49: 0 | BI49: 0 | BJ49: 0 | BK49: 0 | BL49: 19113000 | BM49: 1911305 | BN49: 17201695 | BO49: 90 | BP49: CISF Non-Plan CapEx
A50: 6* Computer Services No PRJ NL-N-COM-001 | B50: 174000000 | C50: 81631037 | D50: 71403572 | E50: 1.5303461e+08 | F50: 20965391 | G50: 42718324 | H50: 43503691 | I50: 0 | J50: 43503691 | K50: -785366.41 | L50: 1.3128168e+08 | M50: 38127347 | N50: 71403572 | O50: 1.0953092e+08 | P50: 21750757 | Q50: 0 | R50: 0 | S50: 0 | T50: 0 | U50: 0 | V50: 0 | W50: 0 | X50: 0 | Y50: 0 | Z50: 0 | AA50: 0 | AB50: 0 | AC50: 0 | AD50: 0 | AE50: 0 | AF50: 174000000 | AG50: 81631037 | AH50: 71403572 | AI50: 1.5303461e+08 | AJ50: 20965391 | AK50: Computer Services No | AL50: NL-N-COM-001 | AM50: 6* PRJ NL-N-COM-001 Computer Services No | AN50: 758067125 | AO50: 81631037 | AP50: 676436088 | AQ50: 89.2 | AR50: 497067125 | AS50: 43503691 | AT50: 453563434 | AU50: 91.2 | AV50: 261000000 | AW50: 38127347 | AX50: 222872653 | AY50: 85.4 | AZ50: 0 | BA50: 0 | BB50: 0 | BC50: 0 | BD50: 0 | BE50: 0 | BF50: 0 | BG50: 0 | BH50: 0 | BI50: 0 | BJ50: 0 | BK50: 0 | BL50: 758068010 | BM50: 81631037 | BN50: 676436973 | BO50: 89.2 | BP50: Computer Services No
...

Sheet Analysis
A1: Project ID | B1: NL-N-TS2-001 | C1: =MATCH(B1,Budget!AL3:AL411,0) -> 86 | D1: {=INDEX(Budget!$A$3:$AJ$411,$C$1,1)} -> 6* TPS-II Non Plan CAPE PRJ NL-N-TS2-001 | E1: {=INDEX(Budget!$B$3:$AJ$411,$C$1,$C$2)} -> 25642573 | F1: {=INDEX(Budget!$B$3:$AJ$411,$C$1,$C$2)} -> 25642573 | G1: {=INDEX(Budget!$B$3:$AJ$411,$C$1,$C$2)} -> 25642573 | H1: {=INDEX(Budget!$B$3:$AJ$411,$C$1,$C$2)} -> 25642573
A2: Years | B2: Total of years | C2: =MATCH($B$2,Budget!$B$1:$AF$1,0) -> 1
C3: Plan | D3: Budget | E3: Actual | F3: Commitment | G3: Assigned | H3: Available
C4: {=INDEX(Budget!$AM$3:$AS$411,$C$1,INT($C$2/5)+1)} -> 94100006 | D4: {=INDEX(Budget!$B$3:$AJ$411,$C$1,$C$2)} -> 25642573 | E4: {=INDEX(Budget!$B$3:$AJ$411,$C$1,$C$2+1)} -> 14376988 | F4: {=INDEX(Budget!$B$3:$AJ$411,$C$1,$C$2+2)} -> 5575827.3 | G4: {=INDEX(Budget!$B$3:$AJ$411,$C$1,$C$2+3)} -> 19952816 | H4: {=INDEX(Budget!$B$3:$AJ$411,$C$1,$C$2+4)} -> 5689757.8
